Workbook

Sheet 차례
A1: 단단 문법 — 장마다 주요 단어
A2: 교재 각 장 앞쪽 '이 장의 단어' 쪽과 같은 단어입니다. 같은 권 안에서는 단어가 겹치지 않게 처음 나온 장에만 넣었습니다.
A4: 권 | B4: 장 | C4: 장 이름 | D4: 단어 수
A5: 중1 | B5: 1 | C5: be동사 | D5: =COUNTIF('중1'!$A:$A,B5)
A6: 중1 | B6: 2 | C6: 일반동사 | D6: =COUNTIF('중1'!$A:$A,B6)
A7: 중1 | B7: 3 | C7: 시제 — 진행형과 미래 | D7: =COUNTIF('중1'!$A:$A,B7)
A8: 중1 | B8: 4 | C8: 조동사 | D8: =COUNTIF('중1'!$A:$A,B8)
A9: 중1 | B9: 5 | C9: 명사와 관사 | D9: =COUNTIF('중1'!$A:$A,B9)
A10: 중1 | B10: 6 | C10: 대명사 | D10: =COUNTIF('중1'!$A:$A,B10)
A11: 중1 | B11: 7 | C11: 형용사·부사·비교 | D11: =COUNTIF('중1'!$A:$A,B11)
A12: 중1 | B12: 8 | C12: 문장의 종류 | D12: =COUNTIF('중1'!$A:$A,B12)
A13: 중1 | B13: 9 | C13: 문장의 형식 | D13: =COUNTIF('중1'!$A:$A,B13)
A14: 중1 | B14: 10 | C14: to부정사와 동명사 기초 | D14: =COUNTIF('중1'!$A:$A,B14)
A15: 중1 | B15: 11 | C15: 전치사 | D15: =COUNTIF('중1'!$A:$A,B15)
A16: 중1 | B16: 12 | C16: 접속사 | D16: =COUNTIF('중1'!$A:$A,B16)
C17: 중1 합계 | D17: =SUM(D5:D16)
A19: 중2 | B19: 1 | C19: 문장의 형식 — 5형식 | D19: =COUNTIF('중2'!$A:$A,B19)
A20: 중2 | B20: 2 | C20: 시제 — 현재완료 | D20: =COUNTIF('중2'!$A:$A,B20)
A21: 중2 | B21: 3 | C21: 조동사 | D21: =COUNTIF('중2'!$A:$A,B21)
A22: 중2 | B22: 4 | C22: 수동태 | D22: =COUNTIF('중2'!$A:$A,B22)
A23: 중2 | B23: 5 | C23: to부정사 | D23: =COUNTIF('중2'!$A:$A,B23)
A24: 중2 | B24: 6 | C24: 동명사 | D24: =COUNTIF('중2'!$A:$A,B24)
A25: 중2 | B25: 7 | C25: 분사 | D25: =COUNTIF('중2'!$A:$A,B25)
A26: 중2 | B26: 8 | C26: 대명사 | D26: =COUNTIF('중2'!$A:$A,B26)
A27: 중2 | B27: 9 | C27: 형용사·부사·비교 | D27: =COUNTIF('중2'!$A:$A,B27)
A28: 중2 | B28: 10 | C28: 문장의 종류 | D28: =COUNTIF('중2'!$A:$A,B28)
A29: 중2 | B29: 11 | C29: 접속사와 전치사 | D29: =COUNTIF('중2'!$A:$A,B29)
A30: 중2 | B30: 12 | C30: 관계대명사 | D30: =COUNTIF('중2'!$A:$A,B30)
C31: 중2 합계 | D31: =SUM(D19:D30)
A33: 중3 | B33: 1 | C33: 완료 시제 | D33: =COUNTIF('중3'!$A:$A,B33)
A34: 중3 | B34: 2 | C34: 조동사 | D34: =COUNTIF('중3'!$A:$A,B34)
A35: 중3 | B35: 3 | C35: 수동태 | D35: =COUNTIF('중3'!$A:$A,B35)
A36: 중3 | B36: 4 | C36: to부정사 | D36: =COUNTIF('중3'!$A:$A,B36)
A37: 중3 | B37: 5 | C37: 동명사 | D37: =COUNTIF('중3'!$A:$A,B37)
A38: 중3 | B38: 6 | C38: 분사 | D38: =COUNTIF('중3'!$A:$A,B38)
A39: 중3 | B39: 7 | C39: 비교 | D39: =COUNTIF('중3'!$A:$A,B39)
A40: 중3 | B40: 8 | C40: 접속사 | D40: =COUNTIF('중3'!$A:$A,B40)
A41: 중3 | B41: 9 | C41: 관계사 | D41: =COUNTIF('중3'!$A:$A,B41)
A42: 중3 | B42: 10 | C42: 가정법 | D42: =COUNTIF('중3'!$A:$A,B42)
A43: 중3 | B43: 11 | C43: 일치와 화법 | D43: =COUNTIF('중3'!$A:$A,B43)
...

Sheet 중1
A1: 장 | B1: 장 이름 | C1: 번호 | D1: 단어 | E1: 품사 | F1: 뜻 | G1: 수준 | H1: 이 장에서 나온 횟수 | I1: 예문 (이 장에서) | J1: 예문 해석
A2: 1 | B2: be동사 | C2: 1 | D2: library | E2: 명사 | F2: 도서관 | G2: 기초 | H2: 16 | I2: Leo is in the library now. | J2: Leo 는 지금 도서관에 있다.
A3: 1 | B3: be동사 | C3: 2 | D3: museum | E3: 명사 | F3: 박물관 | G3: 기초 | H3: 10 | I3: Was the museum fun? — No, it wasn't. | J3: 그 박물관은 재미있었니? — 아니, 재미없었어.
A4: 1 | B4: be동사 | C4: 3 | D4: beach | E4: 명사 | F4: 해변 | G4: 기초 | H4: 9 | I4: We were at the beach last weekend. | J4: 우리는 지난 주말에 해변에 있었다.
A5: 1 | B5: be동사 | C5: 4 | D5: ready | E5: 형용사 | F5: 준비된 | G5: 중1 수준 | H5: 10 | I5: Are you ready for the quiz? | J5: 너는 퀴즈 볼 준비가 됐니?
A6: 1 | B6: be동사 | C6: 5 | D6: weekend | E6: 명사 | F6: 주말 | G6: 중1 수준 | H6: 8 | I6: We were at the beach last weekend. | J6: 우리는 지난 주말에 해변에 있었다.
A7: 1 | B7: be동사 | C7: 6 | D7: concert | E7: 명사 | F7: 음악회, 콘서트 | G7: 중1 수준 | H7: 8 | I7: Were you and Yuna at the concert? — No, we weren't. | J7: 너와 Yuna 는 그 콘서트에 있었니? — 아니, 없었어.
A8: 1 | B8: be동사 | C8: 7 | D8: crowded | E8: 형용사 | F8: 붐비는 | G8: 기초 | H8: 6 | I8: The park wasn't crowded on Sunday. | J8: 그 공원은 일요일에 붐비지 않았다.
A9: 1 | B9: be동사 | C9: 8 | D9: gym | E9: 명사 | F9: 체육관 | G9: 중1 수준 | H9: 7 | I9: Were the boys in the gym? — Yes, they were. | J9: 그 남자아이들은 체육관에 있었니? — 응, 있었어.
A10: 1 | B10: be동사 | C10: 9 | D10: quiz | E10: 명사 | F10: 쪽지 시험, 퀴즈 | G10: 중1 수준 | H10: 6 | I10: Are you ready for the quiz? | J10: 너는 퀴즈 볼 준비가 됐니?
A11: 1 | B11: be동사 | C11: 10 | D11: classmate | E11: 명사 | F11: 반 친구 | G11: 중1 수준 | H11: 5 | I11: Jimin and Sam were classmates two years ago. | J11: Jimin 과 Sam 은 2년 전에 반 친구였다.
A12: 1 | B12: be동사 | C12: 11 | D12: brave | E12: 형용사 | F12: 용감한 | G12: 중1 수준 | H12: 4 | I12: You were very brave at the hospital. | J12: 너는 병원에서 아주 용감했다.
A13: 1 | B13: be동사 | C13: 12 | D13: quiet | E13: 형용사 | F13: 조용한 | G13: 기초 | H13: 5 | I13: Mina was a quiet student. | J13: 미나는 조용한 학생이었다.
... A16: 1 | B16: be동사 | C16: 15 | D16: hospital | E16: 명사 | F16: 병원 | G16: 기초 | H16: 3 | I16: You were very brave at the hospital. | J16: 너는 병원에서 아주 용감했다.
A17: 1 | B17: be동사 | C17: 16 | D17: interested | E17: 형용사 | F17: 관심 있는 | G17: 중1 수준 | H17: 3
A18: 1 | B18: be동사 | C18: 17 | D18: kitchen | E18: 명사 | F18: 부엌 | G18: 중1 수준 | H18: 4 | I18: She's in the kitchen.
A19: 1 | B19: be동사 | C19: 18 | D19: yard | E19: 명사 | F19: 마당 | G19: 중1 수준 | H19: 3 | I19: There are three cats in the yard.
A20: 1 | B20: be동사 | C20: 19 | D20: proud | E20: 형용사 | F20: 자랑스러워하는 | G20: 중1 수준 | H20: 2 | I20: I was so proud.
A21: 1 | B21: be동사 | C21: 20 | D21: strict | E21: 형용사 | F21: 엄격한 | G21: 기초 | H21: 2 | I21: Her coach was very strict.
A22: 1 | B22: be동사 | C22: 21 | D22: firefighter | E22: 명사 | F22: 소방관 | G22: 기초 | H22: 2
A23: 1 | B23: be동사 | C23: 22 | D23: mountain | E23: 명사 | F23: 산 | G23: 기초 | H23: 5 | I23: Last weekend, my friends and I were in the mountains. | J23: 지난 주말에 나와 내 친구들은 산에 있었다.
A24: 1 | B24: be동사 | C24: 23 | D24: plenty | E24: 명사 | F24: 많음, 충분한 양 | G24: 중1 수준 | H24: 3
A25: 2 | B25: 일반동사 | C25: 1 | D25: fly | E25: 동사 | F25: 날리다, 날다 | G25: 중1 수준 | H25: 13 | I25: We flew a kite in the park. | J25: 우리는 공원에서 연을 날렸다.
A26: 2 | B26: 일반동사 | C26: 2 | D26: carry | E26: 동사 | F26: 나르다, 들고 가다 | G26: 중1 수준 | H26: 9 | I26: Every day we carried water to them.
A27: 2 | B27: 일반동사 | C27: 3 | D27: drive | E27: 동사 | F27: 운전하다 | G27: 중1 수준 | H27: 8 | I27: My parents don't drive to work. | J27: 우리 부모님은 차를 몰고 출근하지 않으신다.
A28: 2 | B28: 일반동사 | C28: 4 | D28: early | E28: 부사 | F28: 일찍 | G28: 중1 수준 | H28: 10 | I28: My brother doesn't get up early.
A29: 2 | B29: 일반동사 | C29: 5 | D29: teach | E29: 동사 | F29: 가르치다 | G29: 기초 | H29: 10 | I29: My uncle teaches science at a high school. | J29: 우리 삼촌은 고등학교에서 과학을 가르치신다.
A30: 2 | B30: 일반동사 | C30: 6 | D30: cross | E30: 동사 | F30: 건너다 | G30: 중1 수준 | H30: 4 | I30: How did the children cross the river? | J30: 그 아이들은 어떻게 그 강을 건넜니?
A31: 2 | B31: 일반동사 | C31: 7 | D31: cry | E31: 동사 | F31: 울다 | G31: 중1 수준 | H31: 6 | I31: The baby cries at night. | J31: 그 아기는 밤에 운다.
A32: 2 | B32: 일반동사 | C32: 8 | D32: letter | E32: 명사 | F32: 편지 | G32: 기초 | H32: 4 | I32: Somi wrote a letter to her grandma. | J32: Somi 는 할머니께 편지를 썼다.
A33: 2 | B33: 일반동사 | C33: 9 | D33: understand | E33: 동사 | F33: 이해하다 | G33: 중1 수준 | H33: 5
A34: 2 | B34: 일반동사 | C34: 10 | D34: catch | E34: 동사 | F34: (버스를) 잡아타다, 잡다 | G34: 중1 수준 | H34: 3
A35: 2 | B35: 일반동사 | C35: 11 | D35: choose | E35: 동사 | F35: 고르다 | G35: 중1 수준 | H35: 3 | I35: Each student in our class chooses a book every Monday. | J35: 우리 반 학생은 저마다 월요일마다 책을 한 권 고른다.
A36: 2 | B36: 일반동사 | C36: 12 | D36: move | E36: 동사 | F36: 이사하다, 움직이다 | G36: 중1 수준 | H36: 4 | I36: Two years ago, my family moved to Seoul. | J36: 2년 전에 우리 가족은 서울로 이사했다.
A37: 2 | B37: 일반동사 | C37: 13 | D37: together | E37: 부사 | F37: 함께 | G37: 중1 수준 | H37: 4 | I37: In my house, we don't eat breakfast together.
A38: 2 | B38: 일반동사 | C38: 14 | D38: guess | E38: 동사 | F38: 알아맞히다, 추측하다 | G38: 중1 수준 | H38: 2 | I38: We guessed the answer right on the first try.
A39: 2 | B39: 일반동사 | C39: 15 | D39: imagine | E39: 동사 | F39: 상상하다 | G39: 중1 수준 | H39: 2
A40: 2 | B40: 일반동사 | C40: 16 | D40: cook | E40: 동사 | F40: 요리하다 | G40: 기초 | H40: 6 | I40: Dad cooks dinner on Sundays. | J40: 아빠는 일요일마다 저녁을 요리하신다.
A41: 2 | B41: 일반동사 | C41: 17 | D41: breakfast | E41: 명사 | F41: 아침 식사 | G41: 중1 수준 | H41: 4 | I41: I didn't eat breakfast this morning.
A42: 2 | B42: 일반동사 | C42: 18 | D42: shrink | E42: 동사 | F42: 줄어들다 | G42: 중1 수준 | H42: 2
...

Sheet 중2
A1: 장 | B1: 장 이름 | C1: 번호 | D1: 단어 | E1: 품사 | F1: 뜻 | G1: 수준 | H1: 이 장에서 나온 횟수 | I1: 예문 (이 장에서) | J1: 예문 해석
A2: 1 | B2: 문장의 형식 — 5형식 | C2: 1 | D2: name | E2: 동사 | F2: 이름을 짓다 | G2: 중1 수준 | H2: 32 | I2: Mina named her goldfish Bubbles. | J2: Mina 는 자기 금붕어의 이름을 Bubbles 라고 지었다.
A3: 1 | B3: 문장의 형식 — 5형식 | C3: 2 | D3: consider | E3: 동사 | F3: ~라고 여기다 | G3: 중1 수준 | H3: 19 | I3: We all consider Ms. Yoon a great teacher. | J3: 우리는 모두 Yoon 선생님을 훌륭한 선생님으로 여긴다.
A4: 1 | B4: 문장의 형식 — 5형식 | C4: 3 | D4: healthy | E4: 형용사 | F4: 건강한 | G4: 중1 수준 | H4: 14 | I4: Regular exercise and good sleep keep your body healthy. | J4: 규칙적인 운동과 충분한 잠은 너의 몸을 건강하게 유지해 준다.
A5: 1 | B5: 문장의 형식 — 5형식 | C5: 4 | D5: classmate | E5: 명사 | F5: 반 친구 | G5: 중1 수준 | H5: 3 | I5: Our classmates call Daniel Rocket because he runs fast. | J5: 우리 반 친구들은 Daniel 이 빨리 달려서 그를 Rocket 이라고 부른다.
A6: 1 | B6: 문장의 형식 — 5형식 | C6: 5 | D6: elect | E6: 동사 | F6: 선출하다, 뽑다 | G6: 중1 수준 | H6: 6 | I6: We elected Seojun class president yesterday. | J6: 우리는 어제 Seojun 을 반장으로 뽑았다.
A7: 1 | B7: 문장의 형식 — 5형식 | C7: 6 | D7: hero | E7: 명사 | F7: 영웅 | G7: 중1 수준 | H7: 8 | I7: People call him a hero.
A8: 1 | B8: 문장의 형식 — 5형식 | C8: 7 | D8: comfortable | E8: 형용사 | F8: 편안한 | G8: 중1 수준 | H8: 9 | I8: My new shoes make my feet comfortable. | J8: 내 새 신발은 내 발을 편하게 해 준다.
A9: 1 | B9: 문장의 형식 — 5형식 | C9: 8 | D9: column | E9: 명사 | F9: (신문의) 칼럼 | G9: 중1 수준 | H9: 2 | I9: Our school newspaper started a new column this year.
A10: 1 | B10: 문장의 형식 — 5형식 | C10: 9 | D10: symbol | E10: 명사 | F10: 상징 | G10: 중1 수준 | H10: 1 | I10: The art club painted its statue white, and many students consider it a symbol of courage.
A11: 1 | B11: 문장의 형식 — 5형식 | C11: 10 | D11: courage | E11: 명사 | F11: 용기 | G11: 중1 수준 | H11: 1 | I11: The art club painted its statue white, and many students consider it a symbol of courage.
A12: 1 | B12: 문장의 형식 — 5형식 | C12: 11 | D12: pollution | E12: 명사 | F12: 오염 | G12: 중1 수준 | H12: 1 | I12: Sadly, pollution and fewer wild flowers are making bee life difficult, and many scientists consider the situation a warning.
A13: 1 | B13: 문장의 형식 — 5형식 | C13: 12 | D13: situation | E13: 명사 | F13: 상황 | G13: 중1 수준 | H13: 1 | I13: Sadly, pollution and fewer wild flowers are making bee life difficult, and many scientists consider the situation a warning.
A14: 1 | B14: 문장의 형식 — 5형식 | C14: 13 | D14: nervous | E14: 형용사 | F14: 긴장한, 불안한 | G14: 중1 수준 | H14: 7 | I14: The vacuum cleaner made the puppy nervous.
A15: 1 | B15: 문장의 형식 — 5형식 | C15: 14 | D15: impatient | E15: 형용사 | F15: 참을성 없는 | G15: 중1 수준 | H15: 3 | I15: Did the long line make you impatient?
A16: 1 | B16: 문장의 형식 — 5형식 | C16: 15 | D16: leader | E16: 명사 | F16: 지도자, 대표 | G16: 중1 수준 | H16: 4 | I16: We chose Ian our team leader.
A17: 2 | B17: 시제 — 현재완료 | C17: 1 | D17: lose | E17: 동사 | F17: 잃어버리다, 지다 | G17: 중1 수준 | H17: 12 | I17: Oh no! I have lost my library card. | J17: 이런! 나 도서관 카드를 잃어버렸어.
A18: 2 | B18: 시제 — 현재완료 | C18: 2 | D18: laptop | E18: 명사 | F18: 노트북 컴퓨터 | G18: 중1 수준 | H18: 6 | I18: I have used this laptop since 2021.
A19: 2 | B19: 시제 — 현재완료 | C19: 3 | D19: several | E19: 형용사 | F19: 여러, 몇몇의 | G19: 중1 수준 | H19: 6 | I19: Sujin has played the cello in concerts several times.
A20: 2 | B20: 시제 — 현재완료 | C20: 4 | D20: abroad | E20: 부사 | F20: 해외에 | G20: 중1 수준 | H20: 3 | I20: Has your brother ever been abroad? | J20: 네 형은 외국에 가 본 적이 있니?
A21: 2 | B21: 시제 — 현재완료 | C21: 5 | D21: contest | E21: 명사 | F21: 대회 | G21: 중1 수준 | H21: 6 | I21: Mina won a medal at the speech contest last week. | J21: Mina는 지난주에 말하기 대회에서 메달을 땄다.
A22: 2 | B22: 시제 — 현재완료 | C22: 6 | D22: miss | E22: 동사 | F22: 빠지다, 놓치다 | G22: 중1 수준 | H22: 3 | I22: Jane hasn't missed a day since she joined this class. | J22: Jane은 이 반에 들어온 이후로 하루도 결석하지 않았다.
A23: 2 | B23: 시제 — 현재완료 | C23: 7 | D23: asleep | E23: 형용사 | F23: 잠든 | G23: - | H23: 1 | I23: The baby has been asleep for two hours.
A24: 2 | B24: 시제 — 현재완료 | C24: 8 | D24: popular | E24: 형용사 | F24: 인기 있는 | G24: 중1 수준 | H24: 3 | I24: The city history museum, which reopened in May after two years of repairs, has become popular again.
A25: 2 | B25: 시제 — 현재완료 | C25: 9 | D25: speech | E25: 명사 | F25: 말하기, 연설 | G25: 중1 수준 | H25: 3 | I25: Mina won a medal at the speech contest last week. | J25: Mina는 지난주에 말하기 대회에서 메달을 땄다.
A26: 2 | B26: 시제 — 현재완료 | C26: 10 | D26: legend | E26: 명사 | F26: 전설적인 인물 | G26: 중1 수준 | H26: 1 | I26: Fans consider him a legend.
A27: 2 | B27: 시제 — 현재완료 | C27: 11 | D27: notice | E27: 동사 | F27: 알아차리다 | G27: 중1 수준 | H27: 1 | I27: Have you ever noticed that cats almost always land on their feet when they fall?
A28: 2 | B28: 시제 — 현재완료 | C28: 12 | D28: perform | E28: 동사 | F28: 공연하다 | G28: 중1 수준 | H28: 1 | I28: The pianist who is performing at our school tonight has played in more than twenty countries.
A29: 2 | B29: 시제 — 현재완료 | C29: 13 | D29: touch | E29: 동사 | F29: 손대다, 만지다 | G29: 기초 | H29: 2 | I29: The workers have just painted the fence, so don't touch it.
A30: 2 | B30: 시제 — 현재완료 | C30: 14 | D30: history | E30: 명사 | F30: 역사 | G30: 중1 수준 | H30: 2 | I30: The city history museum, which reopened in May after two years of repairs, has become popular again.
A31: 2 | B31: 시제 — 현재완료 | C31: 15 | D31: valuable | E31: 형용사 | F31: 귀중한, 값비싼 | G31: 중1 수준 | H31: 1
A32: 2 | B32: 시제 — 현재완료 | C32: 16 | D32: quite | E32: 부사 | F32: 꽤, 상당히 | G32: 중1 수준 | H32: 1
A33: 3 | B33: 조동사 | C33: 1 | D33: hurry | E33: 동사 | F33: 서두르다 | G33: 중1 수준 | H33: 3 | I33: We had better hurry, or we will be late. | J33: 우리는 서두르는 게 낫다. 안 그러면 늦을 것이다.
A34: 3 | B34: 조동사 | C34: 2 | D34: carry | E34: 동사 | F34: 나르다, 들고 가다 | G34: 중1 수준 | H34: 3 | I34: You had better carry the eggs carefully. | J34: 너는 그 달걀들을 조심해서 옮기는 게 좋겠다.
A35: 3 | B35: 조동사 | C35: 3 | D35: catch | E35: 동사 | F35: (차를) 타다, 잡다 | G35: 중1 수준 | H35: 3 | I35: They'd better leave now if they want to catch the train.
A36: 3 | B36: 조동사 | C36: 4 | D36: spend | E36: 동사 | F36: (시간을) 보내다 | G36: 중1 수준 | H36: 2
A37: 3 | B37: 조동사 | C37: 5 | D37: company | E37: 명사 | F37: 회사 | G37: 중1 수준 | H37: 1 | I37: My aunt, who has worked for the company for twenty years, is used to going to work early in the morning. | J37: 그 회사에서 20년 동안 일해 온 우리 이모는 아침 일찍 출근하는 것에 익숙하다.
A38: 3 | B38: 조동사 | C38: 6 | D38: reply | E38: 동사 | F38: 답장하다 | G38: 중1 수준 | H38: 1 | I38: You had better not reply to that text from a stranger. | J38: 너는 낯선 사람에게서 온 그 문자에 답하지 않는 게 좋겠다.
A39: 3 | B39: 조동사 | C39: 7 | D39: sunscreen | E39: 명사 | F39: 자외선 차단제 | G39: 중1 수준 | H39: 1 | I39: You'd better put on some sunscreen before going out.
A40: 3 | B40: 조동사 | C40: 8 | D40: tool | E40: 명사 | F40: 도구 | G40: 중1 수준 | H40: 1 | I40: The small tools that he kept in his shop were used to open the backs of watches.
...

Sheet 중3
A1: 장 | B1: 장 이름 | C1: 번호 | D1: 단어 | E1: 품사 | F1: 뜻 | G1: 수준 | H1: 이 장에서 나온 횟수 | I1: 예문 (이 장에서) | J1: 예문 해석
A2: 1 | B2: 완료 시제 | C2: 1 | D2: finally | E2: 부사 | F2: 마침내 | G2: 중1 수준 | H2: 14 | I2: Ethan finally found the key he had lost a week before. | J2: Ethan 은 일주일 전에 잃어버렸던 열쇠를 마침내 찾았다.
A3: 1 | B3: 완료 시제 | C3: 2 | D3: realize | E3: 동사 | F3: 깨닫다 | G3: 중1 수준 | H3: 6 | I3: Minho realized that he had left his phone on the bus. | J3: Minho 는 자기 휴대폰을 버스에 두고 내렸다는 것을 깨달았다.
A4: 1 | B4: 완료 시제 | C4: 3 | D4: move | E4: 동사 | F4: 이사하다, 움직이다 | G4: 중1 수준 | H4: 10 | I4: Jake had lived in Busan for ten years before he moved. | J4: Jake 는 이사하기 전까지 부산에서 10년 동안 살았다.
A5: 1 | B5: 완료 시제 | C5: 4 | D5: perform | E5: 동사 | F5: 공연하다, 수행하다 | G5: 중1 수준 | H5: 3 | I5: The actor has been performing at the same theater for ten years. | J5: 그 배우는 10년째 같은 극장에서 공연해 오고 있다.
A6: 1 | B6: 완료 시제 | C6: 5 | D6: belong | E6: 동사 | F6: (~에) 속하다 | G6: 중1 수준 | H6: 2
A7: 1 | B7: 완료 시제 | C7: 6 | D7: disappear | E7: 동사 | F7: 사라지다 | G7: 중1 수준 | H7: 2
A8: 1 | B8: 완료 시제 | C8: 7 | D8: palace | E8: 명사 | F8: 궁전 | G8: 중1 수준 | H8: 2 | I8: The museum guide asked if we had toured the palace before.
A9: 1 | B9: 완료 시제 | C9: 8 | D9: principal | E9: 명사 | F9: 교장 | G9: 중1 수준 | H9: 2 | I9: How long had the students been rehearsing the play when the principal came to watch?
A10: 1 | B10: 완료 시제 | C10: 9 | D10: suddenly | E10: 부사 | F10: 갑자기 | G10: 중1 수준 | H10: 1 | I10: But in the final round, it stopped suddenly.
A11: 1 | B11: 완료 시제 | C11: 10 | D11: theater | E11: 명사 | F11: 극장 | G11: 중1 수준 | H11: 3 | I11: The actor has been performing at the same theater for ten years. | J11: 그 배우는 10년째 같은 극장에서 공연해 오고 있다.
A12: 1 | B12: 완료 시제 | C12: 11 | D12: entire | E12: 형용사 | F12: 전체의, 온 | G12: 중2·3 수준 | H12: 1 | I12: Mina's voice was hoarse because she had been cheering for her team throughout the entire championship game.
A13: 1 | B13: 완료 시제 | C13: 12 | D13: tiny | E13: 형용사 | F13: 아주 작은 | G13: 중1 수준 | H13: 1 | I13: When the documentary crew returned to the island ten years later, the tiny village had grown into a busy town.
A14: 1 | B14: 완료 시제 | C14: 13 | D14: neighbor | E14: 명사 | F14: 이웃 | G14: 중1 수준 | H14: 2 | I14: Not only my mom but also our neighbors love the flowers in our garden. | J14: 엄마뿐만 아니라 이웃들도 우리 정원의 꽃을 좋아한다.
A15: 1 | B15: 완료 시제 | C15: 14 | D15: climb | E15: 동사 | F15: 오르다 | G15: 중1 수준 | H15: 3
A16: 1 | B16: 완료 시제 | C16: 15 | D16: carry | E16: 동사 | F16: 나르다, 들고 가다 | G16: 중1 수준 | H16: 4 | I16: Minho was very hungry at lunch because he had been carrying boxes all morning. | J16: Minho는 아침 내내 상자를 나르고 있었기 때문에 점심때 무척 배가 고팠다.
A17: 2 | B17: 조동사 | C17: 1 | D17: rise | E17: 동사 | F17: 부풀다, 오르다 | G17: 중1 수준 | H17: 7 | I17: The bread dough must have risen well. | J17: 빵 반죽이 잘 부풀었음에 틀림없다.
A18: 2 | B18: 조동사 | C18: 2 | D18: asleep | E18: 형용사 | F18: 잠든 | G18: - | H18: 7 | I18: Dad isn't answering his phone. He might have fallen asleep. | J18: 아빠가 전화를 안 받으신다. 잠이 드셨을지도 모른다.
A19: 2 | B19: 조동사 | C19: 3 | D19: pass | E19: 동사 | F19: 합격하다, 통과하다 | G19: 기초 | H19: 0 | I19: Jisoo is smiling. She must have passed the test. | J19: Jisoo 가 웃고 있다. 그녀는 시험에 합격했음에 틀림없다.
A20: 2 | B20: 조동사 | C20: 4 | D20: receive | E20: 동사 | F20: 받다 | G20: 중1 수준 | H20: 5 | I20: Chris must have received a lot of gifts on his birthday. He was smiling all day. | J20: Chris는 생일에 선물을 많이 받았음에 틀림없다. 그는 하루 종일 웃고 있었다.
A21: 2 | B21: 조동사 | C21: 5 | D21: survive | E21: 동사 | F21: 살아남다, 견뎌 내다 | G21: 중1 수준 | H21: 3 | I21: The scientists who studied this old tree believe that it must have survived several big storms.
A22: 2 | B22: 조동사 | C22: 6 | D22: advance | E22: 명사 | F22: (in ~) 미리 | G22: 중1 수준 | H22: 2 | I22: We should have booked the tickets in advance. | J22: 우리는 표를 미리 예약했어야 했다.
A23: 2 | B23: 조동사 | C23: 7 | D23: dinosaur | E23: 명사 | F23: 공룡 | G23: - | H23: 2 | I23: Scientists are still not sure why the dinosaurs disappeared.
A24: 2 | B24: 조동사 | C24: 8 | D24: goal | E24: 명사 | F24: 골, 득점 | G24: 중1 수준 | H24: 2 | I24: Our team must have scored a goal.
A25: 2 | B25: 조동사 | C25: 9 | D25: huge | E25: 형용사 | F25: 거대한, 엄청난 | G25: 중1 수준 | H25: 2 | I25: Looking at the huge bill, Dad said that we shouldn't have ordered so many desserts.
A26: 2 | B26: 조동사 | C26: 10 | D26: hurry | E26: 동사 | F26: 서두르다 | G26: 중1 수준 | H26: 2
A27: 2 | B27: 조동사 | C27: 11 | D27: island | E27: 명사 | F27: 섬 | G27: 중1 수준 | H27: 3 | I27: The diver who found the old ship must have known the sea around the island very well.
A28: 2 | B28: 조동사 | C28: 12 | D28: note | E28: 명사 | F28: 쪽지, 메모 | G28: 중1 수준 | H28: 2 | I28: The violinist who played at the opening ceremony must have rehearsed the piece for weeks, because she didn't miss a single note.
A29: 2 | B29: 조동사 | C29: 13 | D29: sunlight | E29: 명사 | F29: 햇빛 | G29: - | H29: 2 | I29: The dust from the crash may have blocked sunlight for years.
A30: 2 | B30: 조동사 | C30: 14 | D30: thief | E30: 명사 | F30: 도둑 | G30: 중1 수준 | H30: 1 | I30: At first, I thought a thief might have broken in.
A31: 2 | B31: 조동사 | C31: 15 | D31: asteroid | E31: 명사 | F31: 소행성 | G31: 중1 수준 | H31: 1 | I31: Many believe that a huge asteroid must have hit the Earth about 66 million years ago.
A32: 2 | B32: 조동사 | C32: 16 | D32: confident | E32: 형용사 | F32: 자신감 있는 | G32: 중1 수준 | H32: 1
A33: 2 | B33: 조동사 | C33: 17 | D33: delete | E33: 동사 | F33: 삭제하다, 지우다 | G33: 중2·3 수준 | H33: 1 | I33: You shouldn't have deleted those photos. They were our best ones.
A34: 2 | B34: 조동사 | C34: 18 | D34: footprint | E34: 명사 | F34: 발자국 | G34: 중2·3 수준 | H34: 1 | I34: There are tiny footprints in the snow. A rabbit must have hopped by.
A35: 2 | B35: 조동사 | C35: 19 | D35: notice | E35: 동사 | F35: 알아차리다 | G35: 중1 수준 | H35: 1 | I35: Mia may not have noticed me.
A36: 2 | B36: 조동사 | C36: 20 | D36: several | E36: 형용사 | F36: 몇몇의, 여러 | G36: 중1 수준 | H36: 1 | I36: The scientists who studied this old tree believe that it must have survived several big storms.
A37: 2 | B37: 조동사 | C37: 21 | D37: ground | E37: 명사 | F37: 땅, 지면 | G37: - | H37: 3 | I37: The ground is wet. It must have rained last night. | J37: 땅이 젖어 있다. 어젯밤에 비가 왔음에 틀림없다.
A38: 2 | B38: 조동사 | C38: 22 | D38: sneakers | E38: 명사 | F38: 운동화 | G38: 중1 수준 | H38: 2 | I38: I shouldn't have bought such expensive sneakers. | J38: 나는 그렇게 비싼 운동화를 사지 말았어야 했다.
A39: 3 | B39: 수동태 | C39: 1 | D39: allow | E39: 동사 | F39: 허락하다 | G39: 중1 수준 | H39: 22 | I39: Students are not allowed to use their phones during class. | J39: 학생들은 수업 시간에 휴대폰을 사용하는 것이 허락되지 않는다.
A40: 3 | B40: 수동태 | C40: 2 | D40: interested | E40: 형용사 | F40: 관심 있는 | G40: 중1 수준 | H40: 12 | I40: My older sister is interested in space. | J40: 우리 언니는 우주에 관심이 있다.
...
